Workbook

Sheet קוביות
E1: 2026 | Q1: 2027 | AF1: 2026 | AK1: 2027 | AW1: 2028
A2: PN | B2: Oct | C2: Nov | D2: Dec | E2: Jan | F2: Feb | G2: Mar | H2: Apr | I2: May | J2: June | K2: July | L2: Aug | M2: Sep | N2: Oct | O2: Nov | P2: Dec | Q2: Jan | R2: Feb | S2: Mar | T2: Apr | U2: May | V2: June | W2: total | X2: מטוס | Y2: Inventory | Z2: מלאי חסום | AA2: Qtty per plane | AB2: UR No | AC2: UR Status | AD2: Remarks | AE2: ריק | AF2: Aug | AG2: Sept | AH2: Oct | AI2: Nov | AJ2: Dec | AK2: Jan | AL2: Feb | AM2: Mar | AN2: Apr | AO2: May | AP2: June | AQ2: July | AR2: Aug | AS2: Sept | AT2: Oct | AU2: Nov | AV2: Dec | AW2: Jan | AX2: Feb | AY2: Mar | AZ2: Aug | BA2: Oct | BB2: Total
A3: 30P410170101-501 | D3: 1 | E3: 1 | F3: 2 | H3: 3 | I3: 2 | J3: 3 | K3: 3 | L3: 2 | M3: 2 | N3: 1 | O3: 3 | P3: 2 | Q3: 2 | R3: 2 | S3: 1 | V3: 2 | W3: =SUM(B3:V3) -> 32 | X3: 2340 | Y3: 0 | Z3: 0 | AA3: 2 | AB3: 201639813 | AC3: 35 | AG3: 3 | AI3: 12 | AO3: 3 | AP3: 12 | AW3: 2 | BB3: =SUM(AE3:BA3) -> 32
A4: 30P352132400-501 | H4: 2 | W4: =SUM(B4:V4) -> 2 | X4: 2341 | Y4: 0 | Z4: 0 | AA4: 1 | AB4: #N/A | AC4: #N/A | AH4: 2 | BB4: =SUM(AE4:BA4) -> 2
A5: 30P460164000-501 | F5: 3 | G5: 6 | H5: 6 | I5: 6 | J5: 4 | K5: 6 | L5: 4 | M5: 2 | N5: 4 | O5: 4 | P5: 4 | Q5: 6 | R5: 4 | S5: 4 | T5: 2 | U5: 4 | V5: 4 | W5: =SUM(B5:V5) -> 73 | X5: 2340 | Y5: 0 | Z5: 0 | AA5: 2 | AB5: #N/A | AC5: #N/A | AG5: 15 | AH5: 18 | AL5: 24 | AR5: 16 | BB5: =SUM(AE5:BA5) -> 73
A6: 30P450194101-501 | G6: 1 | H6: 1 | I6: 4 | J6: 4 | K6: 2 | L6: 1 | W6: =SUM(B6:V6) -> 13 | X6: 2340 | Y6: 0 | Z6: 0 | AA6: 1 | AB6: #N/A | AC6: #N/A | AG6: 13 | BB6: =SUM(AE6:BA6) -> 13
A7: 30P310255000-501 | F7: 1 | G7: 1 | W7: =SUM(B7:V7) -> 2 | X7: 2341 | Y7: 0 | Z7: 0 | AA7: 1 | AB7: #N/A | AC7: #N/A | AF7: 1 | AG7: 1 | BB7: =SUM(AE7:BA7) -> 2
A8: 30P315533000-501 | F8: 2 | W8: =SUM(B8:V8) -> 2 | X8: 2341 | Y8: 0 | Z8: 0 | AA8: 1 | AB8: #N/A | AC8: #N/A | AF8: 2 | BB8: =SUM(AE8:BA8) -> 2
A9: 30P450170101-501 | G9: 2 | I9: 3 | J9: 2 | K9: 3 | L9: 2 | M9: 2 | N9: 2 | O9: 2 | P9: 2 | Q9: 2 | R9: 2 | S9: 3 | T9: 1 | U9: 2 | V9: 2 | W9: =SUM(B9:V9) -> 32 | X9: 2341 | Y9: 1 | Z9: 0 | AA9: 1 | AB9: 201632894 | AC9: 35 | AG9: 9 | AJ9: 2 | AK9: 12 | AQ9: 9 | BB9: =SUM(AE9:BA9) -> 32
A10: 4AS3360547-501 | I10: 2 | Q10: 1 | R10: 2 | S10: 2 | T10: 2 | U10: 2 | V10: 2 | W10: =SUM(B10:V10) -> 13 | X10: 2341 | Y10: 16 | Z10: 0 | AA10: 1 | AB10: #N/A | AC10: #N/A | AK10: 2 | AL10: 6 | AO10: 5 | BB10: =SUM(AE10:BA10) -> 13
A11: 30P460162000-501 | B11: 2 | G11: 5 | H11: 6 | I11: 6 | J11: 4 | K11: 6 | L11: 4 | M11: 2 | N11: 4 | O11: 4 | P11: 4 | Q11: 6 | R11: 4 | V11: 4 | W11: =SUM(B11:V11) -> 61 | X11: 2342 | Y11: 0 | Z11: 0 | AA11: 2 | AB11: #N/A | AC11: #N/A | AG11: 21 | AK11: 12 | AM11: 24 | AT11: 4 | BB11: =SUM(AE11:BA11) -> 61
A12: 30P410114100-001 | G12: 1 | W12: =SUM(B12:V12) -> 1 | X12: 2342 | Y12: 0 | Z12: 0 | AA12: 1 | AB12: #N/A | AC12: #N/A | AG12: 1 | BB12: =SUM(AE12:BA12) -> 1
A13: 30P331026600-005 | E13: 6 | G13: 4 | H13: 4 | W13: =SUM(B13:V13) -> 14 | X13: 2342 | Y13: 0 | Z13: 0 | AA13: 4 | AB13: #N/A | AC13: #N/A | AE13: 2 | AF13: 4 | AG13: 8 | BB13: =SUM(AE13:BA13) -> 14
A14: 30P315631300-001 | G14: 30 | I14: 8 | N14: 8 | O14: 16 | P14: 16 | Q14: 16 | R14: 16 | S14: 24 | T14: 8 | U14: 16 | V14: 16 | W14: =SUM(B14:V14) -> 174 | X14: 2342 | Y14: 64 | Z14: 0 | AA14: 8 | AB14: #N/A | AC14: #N/A | AG14: 38 | AM14: 136 | BB14: =SUM(AE14:BA14) -> 174
A15: 30P420163001-501 | G15: 1 | H15: 3 | I15: 3 | J15: 2 | K15: 3 | L15: 2 | M15: 2 | N15: 1 | O15: 3 | P15: 2 | Q15: 2 | R15: 2 | S15: 1 | V15: 2 | W15: =SUM(B15:V15) -> 29 | X15: 2342 | Y15: 0 | Z15: 0 | AA15: 1 | AB15: 201580141 | AC15: 45 | AG15: 2 | AK15: 13 | AQ15: 12 | AW15: 2 | BB15: =SUM(AE15:BA15) -> 29
A16: 30P310154000-001 | I16: 2 | W16: =SUM(B16:V16) -> 2 | X16: 3005 | Y16: 2 | Z16: 0 | AA16: 1 | AB16: #N/A | AC16: #N/A | AE16: 2 | BB16: =SUM(AE16:BA16) -> 2
A17: 30P410178901-501 | H17: 2 | I17: 2 | J17: 3 | K17: 3 | L17: 2 | M17: 1 | N17: 3 | O17: 2 | P17: 2 | Q17: 2 | R17: 2 | S17: 2 | T17: 2 | U17: 1 | W17: =SUM(B17:V17) -> 29 | X17: 3005 | Y17: 0 | Z17: 0 | AA17: 1 | AB17: #N/A | AC17: #N/A | AJ17: 5 | AM17: 12 | AS17: 12 | BB17: =SUM(AE17:BA17) -> 29
A18: 30P312010401-501 | I18: 2 | W18: =SUM(B18:V18) -> 2 | X18: 3005 | Y18: 2 | Z18: 0 | AA18: 1 | AB18: #N/A | AC18: #N/A | AE18: 2 | BB18: =SUM(AE18:BA18) -> 2
A19: 30P331038101-501 | J19: 1 | W19: =SUM(B19:V19) -> 1 | X19: 3005 | Y19: 2 | Z19: 0 | AA19: 1 | AB19: #N/A | AC19: #N/A | AE19: 1 | BB19: =SUM(AE19:BA19) -> 1
A20: 30P460168000-502 | G20: 1 | H20: 2 | I20: 3 | J20: 2 | K20: 3 | L20: 2 | M20: 1 | N20: 2 | O20: 2 | P20: 2 | Q20: 3 | R20: 2 | S20: 2 | T20: 1 | U20: 2 | V20: 2 | W20: =SUM(B20:V20) -> 32 | X20: 3006 | Y20: 1 | Z20: 1 | AA20: 1 | AB20: #N/A | AC20: #N/A | AG20: 11 | AJ20: 12 | AP20: 9 | BB20: =SUM(AE20:BA20) -> 32
A21: 30P450171900-501 | H21: 1 | I21: 3 | J21: 2 | K21: 3 | L21: 2 | M21: 2 | N21: 2 | O21: 2 | P21: 2 | Q21: 2 | R21: 2 | S21: 2 | T21: 2 | U21: 2 | V21: 2 | W21: =SUM(B21:V21) -> 31 | X21: 3006 | Y21: 0 | Z21: 0 | AA21: 1 | AB21: #N/A | AC21: #N/A | AG21: 5 | AJ21: 5 | AL21: 3 | AN21: 12 | AU21: 6 | BB21: =SUM(AE21:BA21) -> 31
A22: 30P450171003-501 | H22: 1 | I22: 3 | J22: 2 | K22: 3 | L22: 2 | M22: 2 | N22: 2 | O22: 2 | P22: 2 | Q22: 2 | R22: 2 | S22: 1 | V22: 2 | W22: =SUM(B22:V22) -> 26 | X22: 3006 | Y22: 0 | Z22: 0 | AA22: 1 | AB22: #N/A | AC22: #N/A | AE22: 1 | AI22: 12 | AO22: 12 | AV22: 1 | BB22: =SUM(AE22:BA22) -> 26
A23: 30P410178702-501 | H23: 1 | I23: 2 | J23: 3 | K23: 3 | L23: 2 | M23: 1 | N23: 3 | O23: 2 | P23: 2 | Q23: 2 | R23: 2 | S23: 2 | T23: 2 | U23: 2 | V23: 2 | W23: =SUM(B23:V23) -> 31 | X23: 3006 | Y23: 0 | Z23: 0 | AA23: 1 | AB23: #N/A | AC23: #N/A | AG23: 12 | AJ23: 4 | AL23: 12 | AS23: 3 | BB23: =SUM(AE23:BA23) -> 31
A24: 30P450171900-502 | I24: 3 | J24: 2 | K24: 3 | L24: 2 | M24: 2 | N24: 2 | O24: 2 | P24: 2 | Q24: 2 | R24: 2 | S24: 2 | T24: 2 | U24: 2 | V24: 2 | W24: =SUM(B24:V24) -> 30 | X24: 3007 | Y24: 1 | Z24: 0 | AA24: 1 | AB24: #N/A | AC24: #N/A | AG24: 9 | AJ24: 5 | AM24: 12 | AS24: 4 | BB24: =SUM(AE24:BA24) -> 30
A25: 30P410133200-002 | I25: 1 | J25: 3 | K25: 3 | L25: 2 | M25: 1 | N25: 3 | O25: 2 | P25: 2 | Q25: 2 | R25: 2 | S25: 2 | T25: 2 | U25: 2 | V25: 2 | W25: =SUM(B25:V25) -> 29 | X25: 3008 | Y25: 2 | Z25: 0 | AA25: 1 | AB25: #N/A | AC25: #N/A | AI25: 5 | AL25: 12 | AR25: 12 | BB25: =SUM(AE25:BA25) -> 29
A26: 30P410179700-501 | I26: 1 | J26: 3 | K26: 3 | L26: 2 | M26: 1 | N26: 3 | O26: 2 | P26: 2 | Q26: 2 | R26: 2 | S26: 2 | T26: 2 | U26: 2 | V26: 2 | W26: =SUM(B26:V26) -> 29 | X26: 3008 | Y26: 2 | Z26: 0 | AA26: 1 | AB26: #N/A | AC26: #N/A | AG26: 7 | AJ26: 5 | AM26: 12 | AS26: 5 | BB26: =SUM(AE26:BA26) -> 29
A27: 30P410118002-501 | J27: 3 | K27: 3 | L27: 2 | M27: 1 | N27: 3 | O27: 2 | P27: 2 | Q27: 2 | R27: 2 | S27: 2 | T27: 2 | U27: 2 | V27: 2 | W27: =SUM(B27:V27) -> 28 | X27: 3008 | Y27: 2 | Z27: 0 | AA27: 1 | AB27: #N/A | AC27: #N/A | AJ27: 5 | AM27: 13 | AS27: 10 | BB27: =SUM(AE27:BA27) -> 28
A28: 30P581601500-501 | J28: 4 | K28: 6 | L28: 4 | M28: 4 | N28: 4 | O28: 4 | P28: 4 | Q28: 4 | R28: 4 | S28: 6 | T28: 2 | U28: 4 | V28: 4 | W28: =SUM(B28:V28) -> 54 | X28: 3009 | Y28: 6 | Z28: 0 | AA28: 2 | AB28: #N/A | AC28: #N/A | AG28: 20 | AK28: 10 | AM28: 24 | BB28: =SUM(AE28:BA28) -> 54
A29: 30P450173200-001 | I29: 3 | J29: 3 | K29: 2 | L29: 2 | M29: 2 | N29: 2 | O29: 2 | P29: 2 | Q29: 2 | R29: 2 | S29: 2 | T29: 2 | U29: 2 | V29: 2 | W29: =SUM(B29:V29) -> 30 | X29: 3009 | Y29: 3 | Z29: 0 | AA29: 1 | AB29: #N/A | AC29: #N/A | AG29: 6 | AH29: 5 | AJ29: 12 | AP29: 7 | BB29: =SUM(AE29:BA29) -> 30
A30: 30P410133200-001 | J30: 3 | K30: 3 | L30: 2 | M30: 1 | N30: 3 | O30: 2 | P30: 2 | Q30: 2 | R30: 2 | S30: 2 | T30: 2 | U30: 2 | V30: 2 | W30: =SUM(B30:V30) -> 28 | X30: 3009 | Y30: 3 | Z30: 0 | AA30: 1 | AB30: #N/A | AC30: #N/A | AG30: 5 | AJ30: 5 | AM30: 12 | AS30: 6 | BB30: =SUM(AE30:BA30) -> 28
A31: 30P450170101-502 | J31: 2 | K31: 3 | L31: 2 | M31: 2 | N31: 2 | O31: 2 | P31: 2 | Q31: 2 | R31: 2 | S31: 3 | T31: 1 | U31: 2 | V31: 2 | W31: =SUM(B31:V31) -> 27 | X31: 3009 | Y31: 3 | Z31: 1 | AA31: 1 | AB31: #N/A | AC31: #N/A | AI31: 12 | AO31: 5 | AQ31: 10 | BB31: =SUM(AE31:BA31) -> 27
A32: 30P450197800-001 | J32: 2 | K32: 2 | L32: 2 | M32: 2 | N32: 2 | O32: 2 | P32: 2 | Q32: 2 | R32: 2 | S32: 3 | T32: 1 | U32: 2 | V32: 2 | W32: =SUM(B32:V32) -> 26 | X32: 3010 | Y32: 4 | Z32: 0 | AA32: 1 | AB32: #N/A | AC32: #N/A | AG32: 8 | AJ32: 4 | AL32: 12 | AR32: 2 | BB32: =SUM(AE32:BA32) -> 26
A33: 30P460161000-501 | I33: 3 | J33: 4 | K33: 6 | L33: 4 | M33: 2 | N33: 4 | O33: 4 | P33: 4 | Q33: 6 | R33: 4 | S33: 4 | T33: 2 | U33: 4 | V33: 4 | W33: =SUM(B33:V33) -> 55 | X33: 3011 | Y33: 11 | Z33: 0 | AA33: 2 | AB33: #N/A | AC33: #N/A | AH33: 22 | AK33: 10 | AM33: 23 | BB33: =SUM(AE33:BA33) -> 55
A34: 30P357207500-501 | M34: 6 | N34: 12 | O34: 8 | P34: 4 | T34: 7 | U34: 8 | V34: 7 | W34: =SUM(B34:V34) -> 52 | X34: 3011 | Y34: 22 | Z34: 0 | AA34: 4 | AB34: #N/A | AC34: #N/A | AI34: 30 | AV34: 22 | BB34: =SUM(AE34:BA34) -> 52
A35: 30P420160001-501 | J35: 2 | K35: 3 | L35: 2 | M35: 2 | N35: 1 | O35: 3 | P35: 2 | Q35: 2 | R35: 2 | S35: 2 | T35: 1 | U35: 2 | V35: 3 | W35: =SUM(B35:V35) -> 27 | X35: 3011 | Y35: 5 | Z35: 0 | AA35: 1 | AB35: #N/A | AC35: #N/A | AI35: 10 | AK35: 12 | AQ35: 5 | BB35: =SUM(AE35:BA35) -> 27
A36: 30P450173001-501 | K36: 3 | L36: 2 | M36: 2 | N36: 2 | O36: 2 | P36: 2 | Q36: 2 | R36: 2 | S36: 2 | T36: 2 | U36: 2 | V36: 2 | W36: =SUM(B36:V36) -> 25 | X36: 3012 | Y36: 6 | Z36: 0 | AA36: 1 | AB36: #N/A | AC36: #N/A | AJ36: 13 | AP36: 12 | BB36: =SUM(AE36:BA36) -> 25
A37: 30P531125500-001 | L37: 2 | M37: 1 | N37: 2 | O37: 2 | P37: 3 | Q37: 2 | R37: 2 | S37: 2 | T37: 1 | U37: 2 | V37: 2 | W37: =SUM(B37:V37) -> 21 | X37: 3013 | Y37: 8 | Z37: 0 | AA37: 1 | AB37: #N/A | AC37: #N/A | AG37: 6 | AI37: 6 | AL37: 6 | AO37: 3 | BB37: =SUM(AE37:BA37) -> 21
A38: 30P450045200-501 | K38: 2 | L38: 2 | M38: 2 | N38: 2 | O38: 2 | P38: 2 | Q38: 2 | R38: 2 | S38: 2 | T38: 2 | U38: 2 | V38: 2 | W38: =SUM(B38:V38) -> 24 | X38: 3013 | Y38: 7 | Z38: 0 | AA38: 1 | AB38: #N/A | AC38: #N/A | AH38: 8 | AL38: 9 | AP38: 7 | BB38: =SUM(AE38:BA38) -> 24
A39: 30P410179600-501 | K39: 2 | L39: 2 | M39: 1 | N39: 3 | O39: 2 | P39: 2 | Q39: 2 | R39: 2 | S39: 2 | T39: 2 | U39: 2 | V39: 2 | W39: =SUM(B39:V39) -> 24 | X39: 3013 | Y39: 7 | Z39: 0 | AA39: 1 | AB39: #N/A | AC39: #N/A | AH39: 1 | AI39: 5 | AK39: 12 | AQ39: 6 | BB39: =SUM(AE39:BA39) -> 24
A40: 30P450193101-501 | K40: 1 | L40: 1 | W40: =SUM(B40:V40) -> 2 | X40: 3013 | Y40: 7 | Z40: 0 | AA40: 1 | AB40: #N/A | AC40: #N/A | AH40: 2 | BB40: =SUM(AE40:BA40) -> 2
...

Sheet דוח מימד
A1: מקרא: צבע בת.הזמנה:
B2: מאחר באספקה
B3: אספקה 2026
A4: 46388 | B4: אספקה2027
A6: PN | B6: Description | C6: מטוס | D6: מטוס ישן | E6: כמות מינימום באספקה | F6: כמות למטוס | G6: מטוס מכסה | H6: סוג מכונה | I6: תחילת ייצור | J6: יציאה לתהליכים 1 | K6: מועד אספקה תהליכים 1 | L6: מועד אספקה תהליכים 2 | M6: ספק תהליכים | N6: הרכבה | O6: צפי אספקה נכון ל25/08 | P6: תאריך הזמנה במערכת | Q6: DDP1 | R6: הערות 25/08/26
A7: 30P331038101-501 | B7: GUIDE | C7: =VLOOKUP(A7,קוביות!A:X,24,0) -> 3005 | D7: 2342 | E7: 12 | I7: =VLOOKUP(A7,'[1]תכנית ייצור'!$D:$H,5,0) -> #N/A | J7: =I7+6 -> #N/A | O7: סופק הכל | P7: סופק הכל | R7: סופק הכל -אין יותר יתרות
A8: 32G410124000-501 | C8: =VLOOKUP(A8,קוביות!A:X,24,0) -> 3019 | D8: 3019 | E8: 16 | F8: 1 | G8: =#REF!+(E8/F8) -> #REF! | I8: V | J8: 46252 | K8: =J8+16 -> 46268 | L8: 46238 | M8: לאסק | O8: 46245 | P8: 46246 | R8: סופק 16/08 ב11/08
A9: 30P410170101-501 | B9: FITTING ASSEMBLY LOWER H/S TRIM ACTUATOR | C9: =VLOOKUP(A9,קוביות!A:X,24,0) -> 2340 | D9: 2340 | E9: 4 | I9: 46152 | J9: V | K9: V | L9: V | M9: לאסק | N9: 3-4 ימים | O9: 46247 | P9: 46251 | R9: סופק 4 יח ב13/08
A10: 30P331026600-005 | B10: CONTOURED WASHER | C10: =VLOOKUP(A10,קוביות!A:X,24,0) -> 2342 | D10: 2342 | E10: 12 | F10: 1 | G10: =#REF!+(E10/F10) -> #REF! | I10: 46183 | J10: 46189 | K10: TBD | L10: אין | M10: תעשייה אווירית | N10: אין | O10: 46254 | P10: =VLOOKUP(A10,'הזמנות פתוחות'!A:D,4,0) -> 46258 | Q10: DDP1 | R10: סופק ב24/08
A11: 30P788311300-001 | C11: טכנולוגיות | D11: טכנולוגיות | E11: 40 | F11: 1 | G11: =#REF!+(E11/F11) -> #REF! | I11: 46101 | J11: #N/A | K11: =J11+16 -> #N/A | L11: אין | M11: אין | N11: אין | O11: 46261 | P11: =VLOOKUP(A11,'הזמנות פתוחות'!A:D,4,0) -> 46204 | R11: אושר למכירה ממתין לאישור ASN
A12: 4AS2830012-001 | C12: =VLOOKUP(A12,קוביות!A:X,24,0) -> 3025 | D12: 3025 | E12: כל ההזמנות | F12: 1 | G12: =#REF!+(E12/F12) -> #REF! | I12: V | J12: V | K12: V | M12: הלברג פסיבציה | O12: 46261 | P12: =VLOOKUP(A12,'הזמנות פתוחות'!A:D,4,0) -> 46434 | R12: אושר למכירה ממתין לאישור ASN
A13: 30P647002200-001 | E13: 16 | O13: 46261 | P13: 46448 | R13: אושר למכירה ממתין לאישור ASN
A14: 30P647002200-002 | E14: 16 | O14: 46261 | P14: 46408 | R14: אושר למכירה ממתין לאישור ASN
A15: 30P357309000-001 | C15: =VLOOKUP(A15,קוביות!A:X,24,0) -> 3015 | D15: 3015 | E15: כל ההזמנות | F15: 1 | G15: =#REF!+(E15/F15) -> #REF! | I15: V | J15: V | K15: V | M15: 0 | N15: אין | O15: 46261 | P15: =VLOOKUP(A15,'הזמנות פתוחות'!A:D,4,0) -> 46247 | R15: אושר למכירה ממתין לאישור ASN
A16: 28141-000-00 | C16: טכנולוגיות | D16: טכנולוגיות | E16: 10 | I16: 46180 | J16: V | K16: 46243 | M16: נדיב -צפי סיום 06/08 לפי תשובה של ספק | O16: 46261 | P16: 46569 | R16: אושר למכירה ממתין לאישור ASN
A17: 30P357308800-001 | B17: RING SEAL POWER CABLE AFT BLKD | C17: =VLOOKUP(A17,קוביות!A:X,24,0) -> 3024 | D17: 3024 | E17: 144 | I17: V | J17: V | M17: 0 | O17: 46261 | P17: =VLOOKUP(A17,'הזמנות פתוחות'!A:D,4,0) -> 46377 | R17: אושר למכירה ממתין לאישור ASN
A18: 30P357207500-501 | B18: SUPPORT ASSY 1.5IN CLAMP-ECS AFT | C18: =VLOOKUP(A18,קוביות!A:X,24,0) -> 3011 | D18: 3011 | E18: 52 | F18: 1 | G18: =#REF!+(E18/F18) -> #REF! | H18: 4 צירים | I18: V | J18: 46246 | K18: 46258 | M18: אביג | N18: 3-4 ימים | O18: 46261 | P18: =VLOOKUP(A18,'הזמנות פתוחות'!A:D,4,0) -> 46266 | R18: ממתין לעדכון תאריך -לפני ASN
A19: 30P410128002-501 | B19: REAR RIB 7 ASSEMBLY | C19: =VLOOKUP(A19,קוביות!A:X,24,0) -> 3014 | D19: 3014 | E19: 8 | F19: 1 | G19: =#REF!+(E19/F19) -> #REF! | I19: 46180 | J19: 46238 | K19: 46246 | L19: 46258 | M19: לאסק | O19: 46261 | P19: =VLOOKUP(A19,'הזמנות פתוחות'!A:D,4,0) -> 46261 | R19: ממתין לעדכון תאריך -לפני ASN
A20: 30P450170101-501 | B20: FITTING 1 HSTA UPPER ATTACH FRONT ASSY L | C20: =VLOOKUP(A20,קוביות!A:X,24,0) -> 2341 | D20: 2341 | E20: 1 | I20: V | J20: נמצא בתיקון | K20: 46258 | M20: לאסק -צפי סיום 23/08 | O20: 46261 | P20: 46235 | R20: ממתין לעדכון תאריך -לפני ASN
A21: 30P141236900-501 | B21: COAT ROD AFT FITTING ASSY | C21: טכנולוגיות | D21: #N/A | E21: 2 | F21: 1 | G21: =#REF!+(E21/F21) -> #REF! | I21: 46201 | J21: 46237 | K21: =J21+16 -> 46253 | L21: אין | M21: אביג | N21: 3-4 ימים | O21: 46261 | P21: =VLOOKUP(A21,'הזמנות פתוחות'!A:D,4,0) -> 46253 | Q21: DDP1 | R21: מוכן ממתין למבקר
A22: 30A2520697-001 | C22: טכנולוגיות | D22: טכנולוגיות | E22: 60 | F22: 1 | G22: =#REF!+(E22/F22) -> #REF! | I22: #N/A | J22: 46238 | K22: 46250 | M22: הלברג | O22: ממתין לאישור | P22: =VLOOKUP(A22,'הזמנות פתוחות'!A:D,4,0) -> 46250 | R22: אושר למכירה ממתין לאישור ASN
A23: 30P317607200-001 | C23: טכנולוגיות | D23: טכנולוגיות | E23: 12 | F23: 1 | G23: =#REF!+(E23/F23) -> #REF! | I23: V | J23: 46238 | K23: 46250 | M23: הלברג | O23: ממתין לאישור | P23: =VLOOKUP(A23,'הזמנות פתוחות'!A:D,4,0) -> 46254 | R23: אושר למכירה ממתין לאישור ASN
A24: 30P531125500-001 | B24: LOCK WASHER | C24: =VLOOKUP(A24,קוביות!A:X,24,0) -> 3013 | D24: 3013 | E24: 54 | F24: 1 | G24: =#REF!+(E24/F24) -> #REF! | I24: V | J24: V | K24: 46237 | L24: 46250 | M24: הלברג | O24: ממתין לאישור | P24: =VLOOKUP(A24,'הזמנות פתוחות'!A:D,4,0) -> 46264 | R24: אושר למכירה ממתין לאישור ASN
A25: 30P450197901-001 | B25: RETAINER PIVOT | C25: =VLOOKUP(A25,קוביות!A:X,24,0) -> 3022 | D25: 3017 | E25: 36 | F25: 1 | G25: =#REF!+(E25/F25) -> #REF! | I25: 46214 | J25: 46219 | K25: 46250 | M25: תעשייה אווירית -13/08 לצפי סיום לפי מרומן | O25: ממתין לאישור | P25: =VLOOKUP(A25,'הזמנות פתוחות'!A:D,4,0) -> 46282 | R25: אושר למכירה ממתין לאישור ASN
A26: 30P450025701-001 | B26: FORMER 17 LEADING EDGE L.H.S | C26: =VLOOKUP(A26,קוביות!A:X,24,0) -> 3030 | D26: 3006 | E26: 17 | F26: 1 | G26: =#REF!+(E26/F26) -> #REF! | I26: =VLOOKUP(A26,'[1]תכנית ייצור'!$B:$H,7,0) -> #N/A | J26: =I26+6 -> #N/A | O26: ממתין לאישור | P26: 46637 | R26: סחורה מוכנה ממתין לאישור אספקה
A27: 30P460185100-001 | C27: =VLOOKUP(A27,קוביות!A:X,24,0) -> 3029 | D27: 3016 | E27: 72 | F27: 1 | G27: =#REF!+(E27/F27) -> #REF! | I27: 46175 | J27: #N/A | K27: =J27+16 -> #N/A | M27: תעשייה אווירית צפי סיום לפי רומן 22.07 -בפועל חזר ב29/07 | O27: ממתין לאישור | P27: 46513 | R27: חלקים מוכנים כל ההזמנות ממתין לאישור אספקה
A28: 30P410181801-001 | C28: =VLOOKUP(A28,קוביות!A:X,24,0) -> 3016 | D28: 3016 | E28: 13 | F28: 1 | G28: =#REF!+(E28/F28) -> #REF! | I28: V | J28: #N/A | K28: =J28+16 -> #N/A | L28: אין | M28: מיקרו צבע | N28: אין | O28: ממתין לאישור | P28: =VLOOKUP(A28,'הזמנות פתוחות'!A:D,4,0) -> 46264 | R28: חלקים מוכנים כל ההזמנות ממתין לאישור אספקה
A29: 30P310029000-007 | C29: =VLOOKUP(A29,קוביות!A:X,24,0) -> 3017 | D29: 3017 | E29: 60 | F29: 1 | G29: =#REF!+(E29/F29) -> #REF! | I29: V | J29: #N/A | K29: =J29+16 -> #N/A | M29: תעשייה אווירית | O29: ממתין לאישור | P29: =VLOOKUP(A29,'הזמנות פתוחות'!A:D,4,0) -> 46363 | R29: חלקים מוכנים כל ההזמנות ממתין לאישור אספקה
A30: 30P410181600-001 | C30: =VLOOKUP(A30,קוביות!A:X,24,0) -> 3018 | D30: 3018 | E30: 27 | F30: 1 | G30: =#REF!+(E30/F30) -> #REF! | I30: V | J30: V | K30: V | M30: מיקרו צבע | O30: ממתין לאישור | P30: =VLOOKUP(A30,'הזמנות פתוחות'!A:D,4,0) -> 46264 | R30: חלקים מוכנים כל ההזמנות ממתין לאישור אספקה
A31: 30P531123200-001 | B31: EXCENTER | C31: =VLOOKUP(A31,קוביות!A:X,24,0) -> 3018 | D31: 3018 | E31: 117 | F31: 1 | G31: =#REF!+(E31/F31) -> #REF! | I31: 46217 | J31: 46235 | K31: =J31+10 -> 46245 | M31: אביג | O31: ממתין לאישור | P31: =VLOOKUP(A31,'הזמנות פתוחות'!A:D,4,0) -> 46257 | R31: חלקים מוכנים כל ההזמנות ממתין לאישור אספקה
A32: 30P450196901-001 | C32: =VLOOKUP(A32,קוביות!A:X,24,0) -> 3019 | D32: 3019 | E32: 24 | F32: 1 | G32: =#REF!+(E32/F32) -> #REF! | I32: 46145 | J32: #N/A | K32: =J32+16 -> #N/A | M32: תעשייה אווירית צפי סיום לפי רומן 30.06 | O32: ממתין לאישור | P32: =VLOOKUP(A32,'הזמנות פתוחות'!A:D,4,0) -> 46317 | R32: חלקים מוכנים כל ההזמנות ממתין לאישור אספקה
A33: 30P410181901-001 | C33: =VLOOKUP(A33,קוביות!A:X,24,0) -> 3019 | D33: 3019 | E33: 28 | F33: 1 | G33: =#REF!+(E33/F33) -> #REF! | I33: V | J33: #N/A | K33: =J33+16 -> #N/A | M33: מיקרו צבע | O33: ממתין לאישור | P33: =VLOOKUP(A33,'הזמנות פתוחות'!A:D,4,0) -> 46264 | R33: חלקים מוכנים כל ההזמנות ממתין לאישור אספקה
A34: 30P410181701-001 | C34: =VLOOKUP(A34,קוביות!A:X,24,0) -> 3019 | D34: 3019 | E34: 20 | I34: V | J34: V | K34: V | M34: מיקרו צבע | O34: ממתין לאישור | P34: =VLOOKUP(A34,'הזמנות פתוחות'!A:D,4,0) -> 46282 | R34: חלקים מוכנים כל ההזמנות ממתין לאישור אספקה
A35: 30P647003200-002 | C35: =VLOOKUP(A35,קוביות!A:X,24,0) -> 3019 | D35: 3019 | E35: 13 | F35: 1 | G35: =#REF!+(E35/F35) -> #REF! | I35: V | J35: #N/A | K35: =J35+16 -> #N/A | M35: גבי שואף | O35: ממתין לאישור | P35: =VLOOKUP(A35,'הזמנות פתוחות'!A:D,4,0) -> 46377 | R35: עבר FAI חלקים מוכנים ממתינים לאישור אספקה
A36: 30P315493700-001 | B36: CAP FITTING | C36: =VLOOKUP(A36,קוביות!A:X,24,0) -> 3020 | D36: 3020 | E36: 40 | F36: 1 | G36: =#REF!+(E36/F36) -> #REF! | I36: 46195 | J36: #N/A | K36: =J36+16 -> #N/A | M36: בז | O36: ממתין לאישור | P36: =VLOOKUP(A36,'הזמנות פתוחות'!A:D,4,0) -> 46405 | R36: חלקים מוכנים כל ההזמנות ממתין לאישור אספקה
A37: 4AS3134024-005 | B37: COVER | C37: =VLOOKUP(A37,קוביות!A:X,24,0) -> 3021 | D37: 3021 | E37: כל ההזמנות | F37: 1 | G37: =#REF!+(E37/F37) -> #REF! | I37: V | J37: #N/A | K37: =J37+16 -> #N/A | M37: נדיב | O37: ממתין לאישור | P37: =VLOOKUP(A37,'הזמנות פתוחות'!A:D,4,0) -> 46405 | R37: חלקים מוכנים כל ההזמנות ממתין לאישור אספקה
A38: 30P430212500-001 | B38: BLOCK SUPPORT H/S UPPER SKIN | C38: =VLOOKUP(A38,קוביות!A:X,24,0) -> 3021 | D38: 3021 | E38: כל ההזמנות | F38: 1 | G38: =#REF!+(E38/F38) -> #REF! | I38: V | J38: V | K38: V | L38: אין | M38: 0 | N38: אין | O38: ממתין לאישור | P38: =VLOOKUP(A38,'הזמנות פתוחות'!A:D,4,0) -> 46293 | R38: חלקים מוכנים כל ההזמנות ממתין לאישור אספקה
A39: 30P420166400-001 | C39: =VLOOKUP(A39,קוביות!A:X,24,0) -> 3021 | D39: 3021 | E39: 48 | I39: =VLOOKUP(A39,'[1]תכנית ייצור'!$B:$H,7,0) -> #N/A | J39: =I39+6 -> #N/A | K39: =J39+16 -> #N/A | M39: 0 | O39: ממתין לאישור | P39: 46531 | R39: חלקים מוכנים כל ההזמנות ממתין לאישור אספקה
A40: 30P450260100-001 | B40: WEDGE TIP HORIZONTAL STABILIZER L.H.S | C40: =VLOOKUP(A40,קוביות!A:X,24,0) -> 3021 | D40: 3021 | E40: 13 | I40: =VLOOKUP(A40,'[1]תכנית ייצור'!$B:$H,7,0) -> 46308 | J40: =I40+6 -> 46314 | K40: =J40+16 -> 46330 | M40: 0 | O40: ממתין לאישור | P40: =VLOOKUP(A40,'הזמנות פתוחות'!A:D,4,0) -> 46331 | R40: חלקים מוכנים - ממתין לאישור אספקה
A41: 30P581656700-001 | B41: SPRING STUD | C41: =VLOOKUP(A41,קוביות!A:X,24,0) -> 3022 | D41: 3022 | E41: 38 | F41: 1 | G41: =#REF!+(E41/F41) -> #REF! | I41: 46176 | J41: #N/A | K41: =J41+16 -> #N/A | M41: 0 | N41: אין | O41: ממתין לאישור | P41: =VLOOKUP(A41,'הזמנות פתוחות'!A:D,4,0) -> 46448 | R41: חלקים מוכנים כל ההזמנות ממתין לאישור אספקה
...

Sheet הזמנות פתוחות
A1: מספר פריט | B1: מספר הזמנה | C1: מספר שורה | D1: תאריך אספקה | E1: שם לקוח | F1: יתרה לאספקה | G1: כמות בה.י. | H1: כמות במחסן
A2: 30A2520443-001 | B2: 7000145015 | C2: 88 | D2: 46174 | E2: תע"א חטיבת כלי טייס אזרחיים | F2: 24
A3: 23174-000-00 | B3: 7000142426 | C3: 352 | D3: 46174 | E3: תע"א חטיבת כלי טייס אזרחיים | F3: 1
A4: 23174-000-00 | B4: 7000142426 | C4: 354 | D4: 46174 | E4: תע"א חטיבת כלי טייס אזרחיים | F4: 1
A5: ‎30P460185100-001‏ | B5: 7000146077 | C5: 252 | D5: 46182 | E5: תע"א חטיבת כלי טייס אזרחיים | F5: 10 | H5: 24
A6: 23374-000-00 | B6: 7000142426 | C6: 410 | D6: 46187 | E6: תע"א חטיבת כלי טייס אזרחיים | F6: 1
A7: 30A2520441-001 | B7: 7000142426 | C7: 304 | D7: 46187 | E7: תע"א חטיבת כלי טייס אזרחיים | F7: 1 | H7: 13
A8: 9009T074-001 | B8: 7000128245 | C8: 8 | D8: 46188 | E8: אלתא מערכות בע"מ | F8: 2
A9: 23177-000-00 | B9: 7000142426 | C9: 62 | D9: 46193 | E9: תע"א חטיבת כלי טייס אזרחיים | F9: 3
A10: 23252-000-00 | B10: 7000142426 | C10: 118 | D10: 46193 | E10: תע"א חטיבת כלי טייס אזרחיים | F10: 3
A11: 30A2520678-001 | B11: 7000142426 | C11: 328 | D11: 46201 | E11: תע"א חטיבת כלי טייס אזרחיים | F11: 24
A12: MCT1233807-001 | B12: 7000100252 | C12: 4 | D12: 46203 | E12: תע"א חטיבת כלי טייס אזרחיים | F12: 2 | G12: 6
A13: MCT1233808-001 | B13: 7000100252 | C13: 6 | D13: 46203 | E13: תע"א חטיבת כלי טייס אזרחיים | F13: 2 | G13: 2
A14: MCT1233829-001 | B14: 7000100252 | C14: 8 | D14: 46203 | E14: תע"א חטיבת כלי טייס אזרחיים | F14: 8 | G14: 8
A15: 30A2720512-001 | B15: 7000142426 | C15: 64 | D15: 46204 | E15: תע"א חטיבת כלי טייס אזרחיים | F15: 1
A16: 26043-000-00-R3 | B16: 7000142426 | C16: 70 | D16: 46204 | E16: תע"א חטיבת כלי טייס אזרחיים | F16: 46
A17: 23113-000-00 | B17: 7000142426 | C17: 88 | D17: 46204 | E17: תע"א חטיבת כלי טייס אזרחיים | F17: 96
A18: 23113-000-00 | B18: 7000142426 | C18: 90 | D18: 46204 | E18: תע"א חטיבת כלי טייס אזרחיים | F18: 84
A19: 28154-000-00 | B19: 7000142426 | C19: 108 | D19: 46204 | E19: תע"א חטיבת כלי טייס אזרחיים | F19: 1
A20: 23137-000-00 | B20: 7000142426 | C20: 112 | D20: 46204 | E20: תע"א חטיבת כלי טייס אזרחיים | F20: 2
A21: 30A2520756-001 | B21: 7000142426 | C21: 306 | D21: 46204 | E21: תע"א חטיבת כלי טייס אזרחיים | F21: 24
A22: 26046-000-00 | B22: 7000142426 | C22: 308 | D22: 46204 | E22: תע"א חטיבת כלי טייס אזרחיים | F22: 48
A23: 23358-000-00-R2 | B23: 7000142426 | C23: 188 | D23: 46204 | E23: תע"א חטיבת כלי טייס אזרחיים | F23: 12
A24: 26237-000-00 | B24: 7000142426 | C24: 276 | D24: 46204 | E24: תע"א חטיבת כלי טייס אזרחיים | F24: 28
A25: 23422-000-00 | B25: 7000142426 | C25: 196 | D25: 46204 | E25: תע"א חטיבת כלי טייס אזרחיים | F25: 1
A26: 23133-000-00 | B26: 7000142426 | C26: 202 | D26: 46204 | E26: תע"א חטיבת כלי טייס אזרחיים | F26: 2
... A48: KTR1521002-001 | B48: L000290078 | C48: 60 | D48: 46208 | E48: תע"א חטיבת כלי טייס אזרחיים | F48: 12
A49: KTR1521002-001 | B49: L000290078 | C49: 62 | D49: 46208 | E49: תע"א חטיבת כלי טייס אזרחיים | F49: 24 | G49: 93
A50: KTR1521002-001 | B50: L000290078 | C50: 66 | D50: 46208 | E50: תע"א חטיבת כלי טייס אזרחיים | F50: 8
A51: KTR1521002-001 | B51: L000290078 | C51: 68 | D51: 46208 | E51: תע"א חטיבת כלי טייס אזרחיים | F51: 12
A52: KTR1521002-001 | B52: L000290078 | C52: 70 | D52: 46208 | E52: תע"א חטיבת כלי טייס אזרחיים | F52: 6
A53: KTR1521020-001 | B53: L000296094 | C53: 42 | D53: 46208 | E53: תע"א חטיבת כלי טייס אזרחיים | F53: 2 | G53: 29
A54: 30A2520482-001 | B54: L000252352 | C54: 18 | D54: 46211 | E54: תע"א חטיבת כלי טייס אזרחיים | F54: 20
A55: UCP-280-12714-000 | B55: 7000160556 | C55: 2 | D55: 46212 | E55: תעשייה אווירית לישראל בע"מ /מל"מ | F55: 9 | G55: 15 | H55: 7
A56: TNK2102301-001 | B56: L000239521 | C56: 18 | D56: 46215 | E56: תע"א חטיבת כלי טייס אזרחיים | F56: 9 | G56: 78
A57: ‎PAL1311210-001‏ | B57: L000296094 | C57: 124 | D57: 46215 | E57: תע"א חטיבת כלי טייס אזרחיים | F57: 2
A58: ‎PAL1311210-001‏ | B58: L000296094 | C58: 126 | D58: 46215 | E58: תע"א חטיבת כלי טייס אזרחיים | F58: 2
A59: PAL1369223-001 | B59: L000273008 | C59: 94 | D59: 46217 | E59: תע"א חטיבת כלי טייס אזרחיים | F59: 7 | G59: 27
A60: PAL1369223-001 | B60: L000273008 | C60: 96 | D60: 46217 | E60: תע"א חטיבת כלי טייס אזרחיים | F60: 7 | G60: 14
A61: 23067-000-00 | B61: 7000142426 | C61: 76 | D61: 46218 | E61: תע"א חטיבת כלי טייס אזרחיים | F61: 12
...

Sheet גרף
A1: week 1 | B1: week 2 | C1: week 3 | D1: week 4 | E1: week 5 | F1: week 6 | G1: week 7 | H1: week 8 | I1: week 10 | J1: week 12 | K1: week 13 | L1: week 16 | M1: week 17 | N1: week 18 | O1: week 19 | P1: week 20 | Q1: week 22 | R1: week 23 | S1: week 25 | T1: week 27 | U1: week 28 | V1: week 30 | W1: week 31 | X1: week 32
A2: 656 | B2: 585 | C2: 474 | D2: 418 | E2: 650 | F2: 602 | G2: 530 | H2: 397 | I2: 626 | J2: 666 | K2: 451 | L2: 542 | M2: 538 | N2: 657 | O2: 531 | P2: 353 | Q2: 409 | R2: 495 | S2: 429 | T2: 396 | U2: 360 | V2: 366 | W2: 362 | X2: 443
